Workbook
Name ГОСТЫ: [1]Списки!$A$11:$A$13
Name ГОСТЫ: [2]Списки!$A$11:$A$13
Name Перевозчик: '[3]127'!$U$27:$U$28
Name ПОРОДЫ: [1]Списки!$A$2:$A$7
Name ПОРОДЫ: [2]Списки!$A$2:$A$7
Name ТОВАРЫ: [1]Списки!$C$11:$C$13
Name ТОВАРЫ: [2]Списки!$C$11:$C$13

Sheet TPP
H5: =TODAY() -> 46054
I6: ООО Лес-Инвест / LLC Les-Invest
I7: 167000, Республика Коми, г. Сыктывкар, ул. 1-ая Промышленная, 72 / 167000, Republic of Komi, Syktyvkar, st. 1st Industrial, 72
I9: ИНН | J9: 1101091334
I10: КПП | J10: 110101001
C21: =TOTAL!M180 -> #REF!
C22: =TOTAL!M181 -> #REF!
C26: =TOTAL!M159 -> #REF!
C27: =TOTAL!M160 -> SUITE C, LEVEL 7, WORLD TRUST TOWER, 50 STANLEY STREET, CENTRAL, HONG KONG
C30: =TOTAL!M164 -> #REF!
C31: =TOTAL!M165 -> #REF!
C34: =CONCATENATE(TOTAL!M161&" от "&TOTAL!M162) -> #REF!
E35: 1231-1306
E37: -
K39: =ROWS(TOTAL!82:159)-1 -> 77 | L39: pieces,
B40: RZZU0016092,RZZU0006772,RZZU0038342,RZZU0006094,RZZU0037027,RZZU0002490,RZZU0001256,FELU1515544,RZZU0038337,RZZU0038701,RZZU0011465,RZZU0036822,RZZU0001317,RZZU0001955,RZZU0036653,RZZU0001301,RZZU0001750,RZZU0037222,RZZU0009426,RZZU0038928,CRSU9316151,RZZU0037367,RZZU0025089,RZZU0001786,RZZU0027672,RZZU0023229,RZZU0011146,RZZU0014248,RZZU0037156,RZZU0018881,RZZU0012266,RZZU0027348,RZZU0010920,RZZU0037325,RZZU0010659,RZZU0010216,RZZU0016718,RZZU0037140,RZZU0003773,RZZU0017761,RZZU0037182,RZZU0036993,RZZU0009977,RZZU0001472,RZZU0037346,RZZU0037304,RZZU0037351,RZZU0037979,RZZU0011681,SEKU5557836,SEKU5558149,RZZU0036951,RZZU0036967,RZZU0013489,CXDU1134685,RZZU0006598,RZZU0037080,RZZU0002340,SEKU5563206,RZZU0003618,RZZU0000218,RZZU0002360,RZZU0006601,RZZU0026763,RZZU0002144,RZZU0027332,RZZU0037454,RZZU0037330,CXDU1678890,CXDU1041242,RZZU0001554,RZZU0027380,RZZU0036669,CXDU1151065,RZZU0025746,RZZU0036648
B46: =IF(TOTAL!M174="railway","By rail from","By rail.Then by sea") -> By rail from | D46: =TOTAL!M172 -> Syktyvkar,Russia | F46: to | G46: =TOTAL!M173 -> #REF!
B49: Номер | C49: Описание товара | H49: Код товара по ТН ВЭД ЕАЭС | I49: Количество мест и вид упаковки | K49: Количество товаров
B50: 1 | C50: =IF(TOTAL!Q82="сосна","Sawn timber Pinus sylvestris (Pine) /Пиломатериалы обрезные (доска) сосна;","Sawn timber, Picea abies (spruce)/Пиломатериалы обрезные (доска) Ель; ") -> #REF! | H50: =IF(TOTAL!Q82="сосна",4407119401,4407129201) -> #REF! | I50: =CONCATENATE(TOTAL!P81&" "&"packages") -> #REF! | K50: =CONCATENATE(TOTAL!N81&" "&"m3") -> #REF!
K51: =CONCATENATE(TOTAL!T81&" "&"kg") -> #REF!
E55: =C34 -> #REF!
B59: =C21 -> #REF!

Sheet Consolidated invoice
A1: Dimension | C1: Grade | D1: Price | E1: Volume, m3 | F1: Amount | G1: Species | H1: Name of list
E2: =SUMPRODUCT(SUMIFS(INDIRECT("'"&$H$2:$H$42&"'!L35:L100"),INDIRECT("'"&$H$2:$H$42&"'!H35:H100"),A2,INDIRECT("'"&$H$2:$H$42&"'!I35:I100"),B2,INDIRECT("'"&$H$2:$H$42&"'!F35:F100"),C2)) -> #REF! | F2: =D2*E2 -> #REF! | G2: =INDIRECT("'"&H2&"'!e35") -> #REF! | H2: =TOTAL!B4 -> 0
E3: =SUMPRODUCT(SUMIFS(INDIRECT("'"&$H$2:$H$42&"'!L35:L100"),INDIRECT("'"&$H$2:$H$42&"'!H35:H100"),A3,INDIRECT("'"&$H$2:$H$42&"'!I35:I100"),B3,INDIRECT("'"&$H$2:$H$42&"'!F35:F100"),C3)) -> #REF! | F3: =D3*E3 -> #REF!
E4: =SUMPRODUCT(SUMIFS(INDIRECT("'"&$H$2:$H$42&"'!L35:L100"),INDIRECT("'"&$H$2:$H$42&"'!H35:H100"),A4,INDIRECT("'"&$H$2:$H$42&"'!I35:I100"),B4,INDIRECT("'"&$H$2:$H$42&"'!F35:F100"),C4)) -> #REF! | F4: =D4*E4 -> #REF!
E5: =SUMPRODUCT(SUMIFS(INDIRECT("'"&$H$2:$H$42&"'!L35:L100"),INDIRECT("'"&$H$2:$H$42&"'!H35:H100"),A5,INDIRECT("'"&$H$2:$H$42&"'!I35:I100"),B5,INDIRECT("'"&$H$2:$H$42&"'!F35:F100"),C5)) -> #REF! | F5: =D5*E5 -> #REF!
E6: =SUMPRODUCT(SUMIFS(INDIRECT("'"&$H$2:$H$42&"'!L35:L100"),INDIRECT("'"&$H$2:$H$42&"'!H35:H100"),A6,INDIRECT("'"&$H$2:$H$42&"'!I35:I100"),B6,INDIRECT("'"&$H$2:$H$42&"'!F35:F100"),C6)) -> #REF! | F6: =D6*E6 -> #REF!
E7: =SUMPRODUCT(SUMIFS(INDIRECT("'"&$H$2:$H$42&"'!L35:L100"),INDIRECT("'"&$H$2:$H$42&"'!H35:H100"),A7,INDIRECT("'"&$H$2:$H$42&"'!I35:I100"),B7,INDIRECT("'"&$H$2:$H$42&"'!F35:F100"),C7)) -> #REF! | F7: =D7*E7 -> #REF!
E8: =SUMPRODUCT(SUMIFS(INDIRECT("'"&$H$2:$H$42&"'!L35:L100"),INDIRECT("'"&$H$2:$H$42&"'!H35:H100"),A8,INDIRECT("'"&$H$2:$H$42&"'!I35:I100"),B8,INDIRECT("'"&$H$2:$H$42&"'!F35:F100"),C8)) -> #REF! | F8: =D8*E8 -> #REF!
E9: =SUMPRODUCT(SUMIFS(INDIRECT("'"&$H$2:$H$42&"'!L35:L100"),INDIRECT("'"&$H$2:$H$42&"'!H35:H100"),A9,INDIRECT("'"&$H$2:$H$42&"'!I35:I100"),B9,INDIRECT("'"&$H$2:$H$42&"'!F35:F100"),C9)) -> #REF! | F9: =D9*E9 -> #REF!
E10: =SUMPRODUCT(SUMIFS(INDIRECT("'"&$H$2:$H$42&"'!L35:L100"),INDIRECT("'"&$H$2:$H$42&"'!H35:H100"),A10,INDIRECT("'"&$H$2:$H$42&"'!I35:I100"),B10,INDIRECT("'"&$H$2:$H$42&"'!F35:F100"),C10)) -> #REF! | F10: =D10*E10 -> #REF!
E11: =SUMPRODUCT(SUMIFS(INDIRECT("'"&$H$2:$H$42&"'!L35:L100"),INDIRECT("'"&$H$2:$H$42&"'!H35:H100"),A11,INDIRECT("'"&$H$2:$H$42&"'!I35:I100"),B11,INDIRECT("'"&$H$2:$H$42&"'!F35:F100"),C11)) -> #REF! | F11: =D11*E11 -> #REF!
E12: =SUMPRODUCT(SUMIFS(INDIRECT("'"&$H$2:$H$42&"'!L35:L100"),INDIRECT("'"&$H$2:$H$42&"'!H35:H100"),A12,INDIRECT("'"&$H$2:$H$42&"'!I35:I100"),B12,INDIRECT("'"&$H$2:$H$42&"'!F35:F100"),C12)) -> #REF! | F12: =D12*E12 -> #REF!
E13: =SUMPRODUCT(SUMIFS(INDIRECT("'"&$H$2:$H$42&"'!L35:L100"),INDIRECT("'"&$H$2:$H$42&"'!H35:H100"),A13,INDIRECT("'"&$H$2:$H$42&"'!I35:I100"),B13,INDIRECT("'"&$H$2:$H$42&"'!F35:F100"),C13)) -> #REF! | F13: =D13*E13 -> #REF!
E14: =SUMPRODUCT(SUMIFS(INDIRECT("'"&$H$2:$H$42&"'!L35:L100"),INDIRECT("'"&$H$2:$H$42&"'!H35:H100"),A14,INDIRECT("'"&$H$2:$H$42&"'!I35:I100"),B14,INDIRECT("'"&$H$2:$H$42&"'!F35:F100"),C14)) -> #REF! | F14: =D14*E14 -> #REF!
... E106: =SUMPRODUCT(SUMIFS(INDIRECT("'"&$H$2:$H$42&"'!L35:L100"),INDIRECT("'"&$H$2:$H$42&"'!H35:H100"),A106,INDIRECT("'"&$H$2:$H$42&"'!I35:I100"),B106,INDIRECT("'"&$H$2:$H$42&"'!F35:F100"),C106)) -> #REF! | F106: =D106*E106 -> #REF!
A107: Total | E107: =SUM(E2:E106) -> #REF! | F107: =SUM(F2:F106) -> #REF!
J108: ="Контракт " &INDIRECT(CONCATENATE(H2,"!S23"))&" инфо на " & COUNTA(H2:H106) & " ктк" -> #REF!
J109: Size | K109: Volume, m3 | L109: Погружено ЯЛП | M109: Погружено ЛИ | N109: Осталось
N110: =K110-L110-M110 -> 0 | O110: =IF(N110<0,"Перегружено") -> FALSE
N111: =K111-L111-M111 -> 0 | O111: =IF(N111<0,"Перегружено") -> FALSE
N112: =K112-L112-M112 -> 0 | O112: =IF(N112<0,"Перегружено") -> FALSE
N113: =K113-L113-M113 -> 0 | O113: =IF(N113<0,"Перегружено") -> FALSE
N114: =K114-L114-M114 -> 0 | O114: =IF(N114<0,"Перегружено") -> FALSE
N115: =K115-L115-M115 -> 0 | O115: =IF(N115<0,"Перегружено") -> FALSE
N116: =K116-L116-M116 -> 0 | O116: =IF(N116<0,"Перегружено") -> FALSE
N117: =K117-L117-M117 -> 0 | O117: =IF(N117<0,"Перегружено") -> FALSE
N118: =K118-L118-M118 -> 0 | O118: =IF(N118<0,"Перегружено") -> FALSE
N119: =K119-L119-M119 -> 0 | O119: =IF(N119<0,"Перегружено") -> FALSE
N120: =K120-L120-M120 -> 0 | O120: =IF(N120<0,"Перегружено") -> FALSE
N121: =K121-L121-M121 -> 0 | O121: =IF(N121<0,"Перегружено") -> FALSE
... N130: =K130-L130-M130 -> 0 | O130: =IF(N130<0,"Перегружено") -> FALSE
J131: Итого | K131: =SUM(K110:K130) -> 0 | L131: =SUM(L110:L130) -> 0 | M131: =SUM(M110:M130) -> 0 | N131: =K131-L131-M131 -> 0 | O131: =IF(N131<0,"Перегружено") -> FALSE

Sheet TOTAL
A3: № | B3: Инвойс № | C3: Дата инвойса | D3: Отгрузочная спецификация № | E3: Дата отгрузочной спецификации | F3: № VGM | G3: Дата VGM | H3: Номер вагона | I3: Номер СМГС | J3: Сопроводительный документ № | K3: ФСС | L3: Номер контейнера | M3: Пломба | N3: Объем номинальный | O3: ДТ | P3: Количество пачек | Q3: Порода дерева | R3: Вес контейнера тара | S3: Вес нетто | T3: Вес брутто | U3: Сумма
A4: Name list | V4: Номер контейнера | W4: Номер СМГС | X4: Номер вагона
B5: =B4+1 -> 1
B6: =B5+1 -> 2
B7: =B6+1 -> 3
B8: =B7+1 -> 4
B9: =B8+1 -> 5
B10: =B9+1 -> 6
B11: =B10+1 -> 7
B12: =B11+1 -> 8
B13: =B12+1 -> 9
B14: =B13+1 -> 10
B15: =B14+1 -> 11
B16: =B15+1 -> 12
... B79: =B78+1 -> 75
N81: =SUM(N82:N159) -> #REF! | P81: =SUM(P82:P159) -> #REF! | R81: =SUM(R82:R159) -> #REF! | S81: =SUM(S82:S159) -> #REF! | T81: =SUM(T82:T159) -> #REF! | U81: =SUM(U82:U83) -> #REF!
A82: 1 | B82: =INDIRECT(CONCATENATE(B4,"!D2")) -> #REF! | C82: =INDIRECT(CONCATENATE(B4,"!F2")) -> #REF! | D82: =B82 -> #REF! | E82: =C82 -> #REF! | F82: =B82 -> #REF! | G82: =C82 -> #REF! | H82: =VLOOKUP(L82,$V$5:$X$80,3,0) -> #REF! | I82: =VLOOKUP(L82,$V$5:$W$80,2,0) -> #REF! | J82: =J4 -> 0 | L82: =INDIRECT(CONCATENATE(TOTAL!B4,"!D6")) -> #REF! | M82: =INDIRECT(CONCATENATE(B4,"!D25")) -> #REF! | N82: =INDIRECT(CONCATENATE(B4,"!L32")) -> #REF! | O82: =O4 -> 0 | P82: =INDIRECT(CONCATENATE(B4,"!K32")) -> #REF! | Q82: =IF(INDIRECT(CONCATENATE(B4,"!E41"))="SPR","ЕЛЬ","СОСНА") -> #REF! | R82: =INDIRECT(CONCATENATE(B4,"!D27")) -> #REF! | S82: =T82-150 -> #REF! | T82: =INDIRECT(CONCATENATE(B4,"!M32")) -> #REF! | U82: =INDIRECT(CONCATENATE(B4,"!O32")) -> #REF!
A83: 2 | B83: =INDIRECT(CONCATENATE(B5,"!D2")) -> #REF! | C83: =INDIRECT(CONCATENATE(B5,"!F2")) -> #REF! | D83: =B83 -> #REF! | E83: =C83 -> #REF! | F83: =B83 -> #REF! | G83: =C83 -> #REF! | H83: =VLOOKUP(L83,$V$5:$X$80,3,0) -> #REF! | I83: =VLOOKUP(L83,$V$5:$W$80,2,0) -> #REF! | J83: =J5 -> 0 | L83: =INDIRECT(CONCATENATE(TOTAL!B5,"!D6")) -> #REF! | M83: =INDIRECT(CONCATENATE(B5,"!D25")) -> #REF! | N83: =INDIRECT(CONCATENATE(B5,"!L32")) -> #REF! | O83: =O5 -> 0 | P83: =INDIRECT(CONCATENATE(B5,"!K32")) -> #REF! | Q83: =IF(INDIRECT(CONCATENATE(B5,"!E41"))="SPR","ЕЛЬ","СОСНА") -> #REF! | R83: =INDIRECT(CONCATENATE(B5,"!D27")) -> #REF! | S83: =T83-150 -> #REF! | T83: =INDIRECT(CONCATENATE(B5,"!M32")) -> #REF! | U83: =INDIRECT(CONCATENATE(B5,"!O32")) -> #REF!
A84: 3 | B84: =INDIRECT(CONCATENATE(B6,"!D2")) -> #REF! | C84: =INDIRECT(CONCATENATE(B6,"!F2")) -> #REF! | D84: =B84 -> #REF! | E84: =C84 -> #REF! | F84: =B84 -> #REF! | G84: =C84 -> #REF! | H84: =VLOOKUP(L84,$V$5:$X$80,3,0) -> #REF! | I84: =VLOOKUP(L84,$V$5:$W$80,2,0) -> #REF! | J84: =J6 -> 0 | L84: =INDIRECT(CONCATENATE(TOTAL!B6,"!D6")) -> #REF! | M84: =INDIRECT(CONCATENATE(B6,"!D25")) -> #REF! | N84: =INDIRECT(CONCATENATE(B6,"!L32")) -> #REF! | O84: =O6 -> 0 | P84: =INDIRECT(CONCATENATE(B6,"!K32")) -> #REF! | Q84: =IF(INDIRECT(CONCATENATE(B6,"!E41"))="SPR","ЕЛЬ","СОСНА") -> #REF! | R84: =INDIRECT(CONCATENATE(B6,"!D27")) -> #REF! | S84: =T84-150 -> #REF! | T84: =INDIRECT(CONCATENATE(B6,"!M32")) -> #REF!
A85: 4 | B85: =INDIRECT(CONCATENATE(B7,"!D2")) -> #REF! | C85: =INDIRECT(CONCATENATE(B7,"!F2")) -> #REF! | D85: =B85 -> #REF! | E85: =C85 -> #REF! | F85: =B85 -> #REF! | G85: =C85 -> #REF! | H85: =VLOOKUP(L85,$V$5:$X$80,3,0) -> #REF! | I85: =VLOOKUP(L85,$V$5:$W$80,2,0) -> #REF! | J85: =J7 -> 0 | L85: =INDIRECT(CONCATENATE(TOTAL!B7,"!D6")) -> #REF! | M85: =INDIRECT(CONCATENATE(B7,"!D25")) -> #REF! | N85: =INDIRECT(CONCATENATE(B7,"!L32")) -> #REF! | O85: =O7 -> 0 | P85: =INDIRECT(CONCATENATE(B7,"!K32")) -> #REF! | Q85: =IF(INDIRECT(CONCATENATE(B7,"!E41"))="SPR","ЕЛЬ","СОСНА") -> #REF! | R85: =INDIRECT(CONCATENATE(B7,"!D27")) -> #REF! | S85: =T85-150 -> #REF! | T85: =INDIRECT(CONCATENATE(B7,"!M32")) -> #REF!
A86: 5 | B86: =INDIRECT(CONCATENATE(B8,"!D2")) -> #REF! | C86: =INDIRECT(CONCATENATE(B8,"!F2")) -> #REF! | D86: =B86 -> #REF! | E86: =C86 -> #REF! | F86: =B86 -> #REF! | G86: =C86 -> #REF! | H86: =VLOOKUP(L86,$V$5:$X$80,3,0) -> #REF! | I86: =VLOOKUP(L86,$V$5:$W$80,2,0) -> #REF! | J86: =J8 -> 0 | L86: =INDIRECT(CONCATENATE(TOTAL!B8,"!D6")) -> #REF! | M86: =INDIRECT(CONCATENATE(B8,"!D25")) -> #REF! | N86: =INDIRECT(CONCATENATE(B8,"!L32")) -> #REF! | O86: =O8 -> 0 | P86: =INDIRECT(CONCATENATE(B8,"!K32")) -> #REF! | Q86: =IF(INDIRECT(CONCATENATE(B8,"!E41"))="SPR","ЕЛЬ","СОСНА") -> #REF! | R86: =INDIRECT(CONCATENATE(B8,"!D27")) -> #REF! | S86: =T86-150 -> #REF! | T86: =INDIRECT(CONCATENATE(B8,"!M32")) -> #REF!
A87: 6 | B87: =INDIRECT(CONCATENATE(B9,"!D2")) -> #REF! | C87: =INDIRECT(CONCATENATE(B9,"!F2")) -> #REF! | D87: =B87 -> #REF! | E87: =C87 -> #REF! | F87: =B87 -> #REF! | G87: =C87 -> #REF! | H87: =VLOOKUP(L87,$V$5:$X$80,3,0) -> #REF! | I87: =VLOOKUP(L87,$V$5:$W$80,2,0) -> #REF! | J87: =J9 -> 0 | L87: =INDIRECT(CONCATENATE(TOTAL!B9,"!D6")) -> #REF! | M87: =INDIRECT(CONCATENATE(B9,"!D25")) -> #REF! | N87: =INDIRECT(CONCATENATE(B9,"!L32")) -> #REF! | O87: =O9 -> 0 | P87: =INDIRECT(CONCATENATE(B9,"!K32")) -> #REF! | Q87: =IF(INDIRECT(CONCATENATE(B9,"!E41"))="SPR","ЕЛЬ","СОСНА") -> #REF! | R87: =INDIRECT(CONCATENATE(B9,"!D27")) -> #REF! | S87: =T87-150 -> #REF! | T87: =INDIRECT(CONCATENATE(B9,"!M32")) -> #REF!
A88: 7 | B88: =INDIRECT(CONCATENATE(B10,"!D2")) -> #REF! | C88: =INDIRECT(CONCATENATE(B10,"!F2")) -> #REF! | D88: =B88 -> #REF! | E88: =C88 -> #REF! | F88: =B88 -> #REF! | G88: =C88 -> #REF! | H88: =VLOOKUP(L88,$V$5:$X$80,3,0) -> #REF! | I88: =VLOOKUP(L88,$V$5:$W$80,2,0) -> #REF! | J88: =J10 -> 0 | L88: =INDIRECT(CONCATENATE(TOTAL!B10,"!D6")) -> #REF! | M88: =INDIRECT(CONCATENATE(B10,"!D25")) -> #REF! | N88: =INDIRECT(CONCATENATE(B10,"!L32")) -> #REF! | O88: =O10 -> 0 | P88: =INDIRECT(CONCATENATE(B10,"!K32")) -> #REF! | Q88: =IF(INDIRECT(CONCATENATE(B10,"!E41"))="SPR","ЕЛЬ","СОСНА") -> #REF! | R88: =INDIRECT(CONCATENATE(B10,"!D27")) -> #REF! | S88: =T88-150 -> #REF! | T88: =INDIRECT(CONCATENATE(B10,"!M32")) -> #REF!
A89: 8 | B89: =INDIRECT(CONCATENATE(B11,"!D2")) -> #REF! | C89: =INDIRECT(CONCATENATE(B11,"!F2")) -> #REF! | D89: =B89 -> #REF! | E89: =C89 -> #REF! | F89: =B89 -> #REF! | G89: =C89 -> #REF! | H89: =VLOOKUP(L89,$V$5:$X$80,3,0) -> #REF! | I89: =VLOOKUP(L89,$V$5:$W$80,2,0) -> #REF! | J89: =J11 -> 0 | L89: =INDIRECT(CONCATENATE(TOTAL!B11,"!D6")) -> #REF! | M89: =INDIRECT(CONCATENATE(B11,"!D25")) -> #REF! | N89: =INDIRECT(CONCATENATE(B11,"!L32")) -> #REF! | O89: =O11 -> 0 | P89: =INDIRECT(CONCATENATE(B11,"!K32")) -> #REF! | Q89: =IF(INDIRECT(CONCATENATE(B11,"!E41"))="SPR","ЕЛЬ","СОСНА") -> #REF! | R89: =INDIRECT(CONCATENATE(B11,"!D27")) -> #REF! | S89: =T89-150 -> #REF! | T89: =INDIRECT(CONCATENATE(B11,"!M32")) -> #REF!
A90: 9 | B90: =INDIRECT(CONCATENATE(B12,"!D2")) -> #REF! | C90: =INDIRECT(CONCATENATE(B12,"!F2")) -> #REF! | D90: =B90 -> #REF! | E90: =C90 -> #REF! | F90: =B90 -> #REF! | G90: =C90 -> #REF! | H90: =VLOOKUP(L90,$V$5:$X$80,3,0) -> #REF! | I90: =VLOOKUP(L90,$V$5:$W$80,2,0) -> #REF! | J90: =J12 -> 0 | L90: =INDIRECT(CONCATENATE(TOTAL!B12,"!D6")) -> #REF! | M90: =INDIRECT(CONCATENATE(B12,"!D25")) -> #REF! | N90: =INDIRECT(CONCATENATE(B12,"!L32")) -> #REF! | O90: =O12 -> 0 | P90: =INDIRECT(CONCATENATE(B12,"!K32")) -> #REF! | Q90: =IF(INDIRECT(CONCATENATE(B12,"!E41"))="SPR","ЕЛЬ","СОСНА") -> #REF! | R90: =INDIRECT(CONCATENATE(B12,"!D27")) -> #REF! | S90: =T90-150 -> #REF! | T90: =INDIRECT(CONCATENATE(B12,"!M32")) -> #REF!
A91: 10 | B91: =INDIRECT(CONCATENATE(B13,"!D2")) -> #REF! | C91: =INDIRECT(CONCATENATE(B13,"!F2")) -> #REF! | D91: =B91 -> #REF! | E91: =C91 -> #REF! | F91: =B91 -> #REF! | G91: =C91 -> #REF! | H91: =VLOOKUP(L91,$V$5:$X$80,3,0) -> #REF! | I91: =VLOOKUP(L91,$V$5:$W$80,2,0) -> #REF! | J91: =J13 -> 0 | L91: =INDIRECT(CONCATENATE(TOTAL!B13,"!D6")) -> #REF! | M91: =INDIRECT(CONCATENATE(B13,"!D25")) -> #REF! | N91: =INDIRECT(CONCATENATE(B13,"!L32")) -> #REF! | O91: =O13 -> 0 | P91: =INDIRECT(CONCATENATE(B13,"!K32")) -> #REF! | Q91: =IF(INDIRECT(CONCATENATE(B13,"!E41"))="SPR","ЕЛЬ","СОСНА") -> #REF! | R91: =INDIRECT(CONCATENATE(B13,"!D27")) -> #REF! | S91: =T91-150 -> #REF! | T91: =INDIRECT(CONCATENATE(B13,"!M32")) -> #REF!
A92: 11 | B92: =INDIRECT(CONCATENATE(B14,"!D2")) -> #REF! | C92: =INDIRECT(CONCATENATE(B14,"!F2")) -> #REF! | D92: =B92 -> #REF! | E92: =C92 -> #REF! | F92: =B92 -> #REF! | G92: =C92 -> #REF! | H92: =VLOOKUP(L92,$V$5:$X$80,3,0) -> #REF! | I92: =VLOOKUP(L92,$V$5:$W$80,2,0) -> #REF! | J92: =J14 -> 0 | L92: =INDIRECT(CONCATENATE(TOTAL!B14,"!D6")) -> #REF! | M92: =INDIRECT(CONCATENATE(B14,"!D25")) -> #REF! | N92: =INDIRECT(CONCATENATE(B14,"!L32")) -> #REF! | O92: =O14 -> 0 | P92: =INDIRECT(CONCATENATE(B14,"!K32")) -> #REF! | Q92: =IF(INDIRECT(CONCATENATE(B14,"!E41"))="SPR","ЕЛЬ","СОСНА") -> #REF! | R92: =INDIRECT(CONCATENATE(B14,"!D27")) -> #REF! | S92: =T92-150 -> #REF! | T92: =INDIRECT(CONCATENATE(B14,"!M32")) -> #REF!
A93: 12 | B93: =INDIRECT(CONCATENATE(B15,"!D2")) -> #REF! | C93: =INDIRECT(CONCATENATE(B15,"!F2")) -> #REF! | D93: =B93 -> #REF! | E93: =C93 -> #REF! | F93: =B93 -> #REF! | G93: =C93 -> #REF! | H93: =VLOOKUP(L93,$V$5:$X$80,3,0) -> #REF! | I93: =VLOOKUP(L93,$V$5:$W$80,2,0) -> #REF! | J93: =J15 -> 0 | L93: =INDIRECT(CONCATENATE(TOTAL!B15,"!D6")) -> #REF! | M93: =INDIRECT(CONCATENATE(B15,"!D25")) -> #REF! | N93: =INDIRECT(CONCATENATE(B15,"!L32")) -> #REF! | O93: =O15 -> 0 | P93: =INDIRECT(CONCATENATE(B15,"!K32")) -> #REF! | Q93: =IF(INDIRECT(CONCATENATE(B15,"!E41"))="SPR","ЕЛЬ","СОСНА") -> #REF! | R93: =INDIRECT(CONCATENATE(B15,"!D27")) -> #REF! | S93: =T93-150 -> #REF! | T93: =INDIRECT(CONCATENATE(B15,"!M32")) -> #REF!
A94: 13 | B94: =INDIRECT(CONCATENATE(B16,"!D2")) -> #REF! | C94: =INDIRECT(CONCATENATE(B16,"!F2")) -> #REF! | D94: =B94 -> #REF! | E94: =C94 -> #REF! | F94: =B94 -> #REF! | G94: =C94 -> #REF! | H94: =VLOOKUP(L94,$V$5:$X$80,3,0) -> #REF! | I94: =VLOOKUP(L94,$V$5:$W$80,2,0) -> #REF! | J94: =J16 -> 0 | L94: =INDIRECT(CONCATENATE(TOTAL!B16,"!D6")) -> #REF! | M94: =INDIRECT(CONCATENATE(B16,"!D25")) -> #REF! | N94: =INDIRECT(CONCATENATE(B16,"!L32")) -> #REF! | O94: =O16 -> 0 | P94: =INDIRECT(CONCATENATE(B16,"!K32")) -> #REF! | Q94: =IF(INDIRECT(CONCATENATE(B16,"!E41"))="SPR","ЕЛЬ","СОСНА") -> #REF! | R94: =INDIRECT(CONCATENATE(B16,"!D27")) -> #REF! | S94: =T94-150 -> #REF! | T94: =INDIRECT(CONCATENATE(B16,"!M32")) -> #REF!
A95: 14 | B95: =INDIRECT(CONCATENATE(B17,"!D2")) -> #REF! | C95: =INDIRECT(CONCATENATE(B17,"!F2")) -> #REF! | D95: =B95 -> #REF! | E95: =C95 -> #REF! | F95: =B95 -> #REF! | G95: =C95 -> #REF! | H95: =VLOOKUP(L95,$V$5:$X$80,3,0) -> #REF! | I95: =VLOOKUP(L95,$V$5:$W$80,2,0) -> #REF! | J95: =J17 -> 0 | L95: =INDIRECT(CONCATENATE(TOTAL!B17,"!D6")) -> #REF! | M95: =INDIRECT(CONCATENATE(B17,"!D25")) -> #REF! | N95: =INDIRECT(CONCATENATE(B17,"!L32")) -> #REF! | O95: =O17 -> 0 | P95: =INDIRECT(CONCATENATE(B17,"!K32")) -> #REF! | Q95: =IF(INDIRECT(CONCATENATE(B17,"!E41"))="SPR","ЕЛЬ","СОСНА") -> #REF! | R95: =INDIRECT(CONCATENATE(B17,"!D27")) -> #REF! | S95: =T95-150 -> #REF! | T95: =INDIRECT(CONCATENATE(B17,"!M32")) -> #REF!
... A157: 76 | B157: =INDIRECT(CONCATENATE(B79,"!D2")) -> #REF! | C157: =INDIRECT(CONCATENATE(B79,"!F2")) -> #REF! | D157: =B157 -> #REF! | E157: =C157 -> #REF! | F157: =B157 -> #REF! | G157: =C157 -> #REF! | H157: =VLOOKUP(L157,$V$5:$X$80,3,0) -> #REF! | I157: =VLOOKUP(L157,$V$5:$W$80,2,0) -> #REF! | J157: =J79 -> 0 | L157: =INDIRECT(CONCATENATE(TOTAL!B79,"!D6")) -> #REF! | M157: =INDIRECT(CONCATENATE(B79,"!D25")) -> #REF! | N157: =INDIRECT(CONCATENATE(B79,"!L32")) -> #REF! | O157: =O79 -> 0 | P157: =INDIRECT(CONCATENATE(B79,"!K32")) -> #REF! | Q157: =IF(INDIRECT(CONCATENATE(B79,"!E41"))="SPR","ЕЛЬ","СОСНА") -> #REF! | R157: =INDIRECT(CONCATENATE(B79,"!D27")) -> #REF! | S157: =T157-150 -> #REF! | T157: =INDIRECT(CONCATENATE(B79,"!M32")) -> #REF!
L159: Buyer/Покупатель | M159: =INDIRECT(CONCATENATE(B4,"!S16")) -> #REF!
M160: SUITE C, LEVEL 7, WORLD TRUST TOWER, 50 STANLEY STREET, CENTRAL, HONG KONG
L161: № Contract/№ контракта | M161: =INDIRECT(CONCATENATE(B4,"!S20")) -> #REF!
L162: Date of Contract/Дата контракта | M162: =INDIRECT(CONCATENATE(B4,"!S21")) -> #REF!
L164: Consignee/Грузополучатель: | M164: =INDIRECT(CONCATENATE(B4,"!S17")) -> #REF!
L165: Adress/Адрес: | M165: =INDIRECT(CONCATENATE(B4,"!S18")) -> #REF!
L167: Notify/Уведомить: | M167: =M164 -> #REF!
L168: Adress/По Адресу: | M168: =M165 -> #REF!
L169: Tel/Телефон: | M169: =INDIRECT(CONCATENATE(B4,"!S19")) -> #REF!
...
